[2025-05-08T10:29:14.894+0000] {local_task_job_runner.py:120} INFO - ::group::Pre task execution logs
[2025-05-08T10:29:14.981+0000] {taskinstance.py:2076} INFO - Dependencies all met for dep_context=non-requeueable deps ti=<TaskInstance: e_commerce_dw_etl_decorator.extract.extract_and_load_to_staging manual__2025-05-08T10:29:14.382778+00:00 [queued]>
[2025-05-08T10:29:14.993+0000] {taskinstance.py:2076} INFO - Dependencies all met for dep_context=requeueable deps ti=<TaskInstance: e_commerce_dw_etl_decorator.extract.extract_and_load_to_staging manual__2025-05-08T10:29:14.382778+00:00 [queued]>
[2025-05-08T10:29:14.994+0000] {taskinstance.py:2306} INFO - Starting attempt 1 of 1
[2025-05-08T10:29:15.011+0000] {taskinstance.py:2330} INFO - Executing <Task(PythonOperator): extract.extract_and_load_to_staging> on 2025-05-08 10:29:14.382778+00:00
[2025-05-08T10:29:15.021+0000] {standard_task_runner.py:63} INFO - Started process 932 to run task
[2025-05-08T10:29:15.026+0000] {standard_task_runner.py:90} INFO - Running: ['***', 'tasks', 'run', 'e_commerce_dw_etl_decorator', 'extract.extract_and_load_to_staging', 'manual__2025-05-08T10:29:14.382778+00:00', '--job-id', '102', '--raw', '--subdir', 'DAGS_FOLDER/ecommerce_dw_dag.py', '--cfg-path', '/tmp/tmpixk0d7m_']
[2025-05-08T10:29:15.030+0000] {standard_task_runner.py:91} INFO - Job 102: Subtask extract.extract_and_load_to_staging
[2025-05-08T10:29:15.088+0000] {task_command.py:426} INFO - Running <TaskInstance: e_commerce_dw_etl_decorator.extract.extract_and_load_to_staging manual__2025-05-08T10:29:14.382778+00:00 [running]> on host ebff8b55cad8
[2025-05-08T10:29:15.415+0000] {taskinstance.py:2648} INFO - Exporting env vars: AIRFLOW_CTX_DAG_OWNER='***' AIRFLOW_CTX_DAG_ID='e_commerce_dw_etl_decorator' AIRFLOW_CTX_TASK_ID='extract.extract_and_load_to_staging' AIRFLOW_CTX_EXECUTION_DATE='2025-05-08T10:29:14.382778+00:00' AIRFLOW_CTX_TRY_NUMBER='1' AIRFLOW_CTX_DAG_RUN_ID='manual__2025-05-08T10:29:14.382778+00:00'
[2025-05-08T10:29:15.417+0000] {taskinstance.py:430} INFO - ::endgroup::
[2025-05-08T10:29:15.430+0000] {base.py:84} INFO - Using connection ID 'mysql' for task execution.
[2025-05-08T10:29:15.450+0000] {base.py:84} INFO - Using connection ID 'mysql' for task execution.
[2025-05-08T10:29:15.464+0000] {logging_mixin.py:188} WARNING - /home/***/.local/lib/python3.10/site-packages/***/providers/common/sql/hooks/sql.py:263 UserWarning: pandas only supports SQLAlchemy connectable (engine/connection) or database string URI or sqlite3 DBAPI2 connection. Other DBAPI2 objects are not tested. Please consider using SQLAlchemy.
[2025-05-08T10:29:15.992+0000] {base.py:84} INFO - Using connection ID 'postgres' for task execution.
[2025-05-08T10:29:16.080+0000] {taskinstance.py:441} INFO - ::group::Post task execution logs
[2025-05-08T10:29:16.081+0000] {taskinstance.py:2905} ERROR - Task failed with exception
Traceback (most recent call last):
  File "/home/airflow/.local/lib/python3.10/site-packages/sqlalchemy/engine/base.py", line 1910, in _execute_context
    self.dialect.do_execute(
  File "/home/airflow/.local/lib/python3.10/site-packages/sqlalchemy/engine/default.py", line 736, in do_execute
    cursor.execute(statement, parameters)
psycopg2.errors.InvalidSchemaName: schema "staging" does not exist
LINE 2: CREATE TABLE staging.stg_order_reviews (
                     ^


The above exception was the direct cause of the following exception:

Traceback (most recent call last):
  File "/home/airflow/.local/lib/python3.10/site-packages/airflow/models/taskinstance.py", line 465, in _execute_task
    result = _execute_callable(context=context, **execute_callable_kwargs)
  File "/home/airflow/.local/lib/python3.10/site-packages/airflow/models/taskinstance.py", line 432, in _execute_callable
    return execute_callable(context=context, **execute_callable_kwargs)
  File "/home/airflow/.local/lib/python3.10/site-packages/airflow/models/baseoperator.py", line 401, in wrapper
    return func(self, *args, **kwargs)
  File "/home/airflow/.local/lib/python3.10/site-packages/airflow/operators/python.py", line 235, in execute
    return_value = self.execute_callable()
  File "/home/airflow/.local/lib/python3.10/site-packages/airflow/operators/python.py", line 252, in execute_callable
    return self.python_callable(*self.op_args, **self.op_kwargs)
  File "/opt/airflow/dags/extract_and_load_to_staging.py", line 31, in extract_and_load_to_staging
    staging_operator.save_dataframe_to_postgres(df, f"stg_{table}", schema="staging", if_exists="replace")
  File "/opt/airflow/plugins/postgresql_operator.py", line 20, in save_dataframe_to_postgres
    df.to_sql(table_name,
  File "/home/airflow/.local/lib/python3.10/site-packages/pandas/core/generic.py", line 2987, in to_sql
    return sql.to_sql(
  File "/home/airflow/.local/lib/python3.10/site-packages/pandas/io/sql.py", line 695, in to_sql
    return pandas_sql.to_sql(
  File "/home/airflow/.local/lib/python3.10/site-packages/pandas/io/sql.py", line 1728, in to_sql
    table = self.prep_table(
  File "/home/airflow/.local/lib/python3.10/site-packages/pandas/io/sql.py", line 1631, in prep_table
    table.create()
  File "/home/airflow/.local/lib/python3.10/site-packages/pandas/io/sql.py", line 838, in create
    self._execute_create()
  File "/home/airflow/.local/lib/python3.10/site-packages/pandas/io/sql.py", line 824, in _execute_create
    self.table.create(bind=self.pd_sql.connectable)
  File "/home/airflow/.local/lib/python3.10/site-packages/sqlalchemy/sql/schema.py", line 962, in create
    bind._run_ddl_visitor(ddl.SchemaGenerator, self, checkfirst=checkfirst)
  File "/home/airflow/.local/lib/python3.10/site-packages/sqlalchemy/engine/base.py", line 3238, in _run_ddl_visitor
    conn._run_ddl_visitor(visitorcallable, element, **kwargs)
  File "/home/airflow/.local/lib/python3.10/site-packages/sqlalchemy/engine/base.py", line 2221, in _run_ddl_visitor
    visitorcallable(self.dialect, self, **kwargs).traverse_single(element)
  File "/home/airflow/.local/lib/python3.10/site-packages/sqlalchemy/sql/visitors.py", line 524, in traverse_single
    return meth(obj, **kw)
  File "/home/airflow/.local/lib/python3.10/site-packages/sqlalchemy/sql/ddl.py", line 899, in visit_table
    self.connection.execute(
  File "/home/airflow/.local/lib/python3.10/site-packages/sqlalchemy/engine/base.py", line 1385, in execute
    return meth(self, multiparams, params, _EMPTY_EXECUTION_OPTS)
  File "/home/airflow/.local/lib/python3.10/site-packages/sqlalchemy/sql/ddl.py", line 80, in _execute_on_connection
    return connection._execute_ddl(
  File "/home/airflow/.local/lib/python3.10/site-packages/sqlalchemy/engine/base.py", line 1477, in _execute_ddl
    ret = self._execute_context(
  File "/home/airflow/.local/lib/python3.10/site-packages/sqlalchemy/engine/base.py", line 1953, in _execute_context
    self._handle_dbapi_exception(
  File "/home/airflow/.local/lib/python3.10/site-packages/sqlalchemy/engine/base.py", line 2134, in _handle_dbapi_exception
    util.raise_(
  File "/home/airflow/.local/lib/python3.10/site-packages/sqlalchemy/util/compat.py", line 211, in raise_
    raise exception
  File "/home/airflow/.local/lib/python3.10/site-packages/sqlalchemy/engine/base.py", line 1910, in _execute_context
    self.dialect.do_execute(
  File "/home/airflow/.local/lib/python3.10/site-packages/sqlalchemy/engine/default.py", line 736, in do_execute
    cursor.execute(statement, parameters)
sqlalchemy.exc.ProgrammingError: (psycopg2.errors.InvalidSchemaName) schema "staging" does not exist
LINE 2: CREATE TABLE staging.stg_order_reviews (
                     ^

[SQL: 
CREATE TABLE staging.stg_order_reviews (
	review_id TEXT, 
	order_id TEXT, 
	review_score BIGINT, 
	review_comment_title TEXT, 
	review_comment_message TEXT, 
	review_creation_date DATE, 
	review_answer_timestamp DATE
)

]
(Background on this error at: https://sqlalche.me/e/14/f405)
[2025-05-08T10:29:16.110+0000] {taskinstance.py:1206} INFO - Marking task as FAILED. dag_id=e_commerce_dw_etl_decorator, task_id=extract.extract_and_load_to_staging, run_id=manual__2025-05-08T10:29:14.382778+00:00, execution_date=20250508T102914, start_date=20250508T102914, end_date=20250508T102916
[2025-05-08T10:29:16.127+0000] {standard_task_runner.py:110} ERROR - Failed to execute job 102 for task extract.extract_and_load_to_staging ((psycopg2.errors.InvalidSchemaName) schema "staging" does not exist
LINE 2: CREATE TABLE staging.stg_order_reviews (
                     ^

[SQL: 
CREATE TABLE staging.stg_order_reviews (
	review_id TEXT, 
	order_id TEXT, 
	review_score BIGINT, 
	review_comment_title TEXT, 
	review_comment_message TEXT, 
	review_creation_date DATE, 
	review_answer_timestamp DATE
)

]
(Background on this error at: https://sqlalche.me/e/14/f405); 932)
[2025-05-08T10:29:16.170+0000] {local_task_job_runner.py:240} INFO - Task exited with return code 1
[2025-05-08T10:29:16.190+0000] {taskinstance.py:3503} INFO - 0 downstream tasks scheduled from follow-on schedule check
[2025-05-08T10:29:16.194+0000] {local_task_job_runner.py:222} INFO - ::endgroup::
