[2025-05-08T14:59:41.868+0000] {local_task_job_runner.py:120} INFO - ::group::Pre task execution logs
[2025-05-08T14:59:41.955+0000] {taskinstance.py:2076} INFO - Dependencies all met for dep_context=non-requeueable deps ti=<TaskInstance: e_commerce_dw_etl_decorator.load.load_fact_orders manual__2025-05-08T14:58:40.551626+00:00 [queued]>
[2025-05-08T14:59:41.974+0000] {taskinstance.py:2076} INFO - Dependencies all met for dep_context=requeueable deps ti=<TaskInstance: e_commerce_dw_etl_decorator.load.load_fact_orders manual__2025-05-08T14:58:40.551626+00:00 [queued]>
[2025-05-08T14:59:41.975+0000] {taskinstance.py:2306} INFO - Starting attempt 1 of 1
[2025-05-08T14:59:42.027+0000] {taskinstance.py:2330} INFO - Executing <Task(PythonOperator): load.load_fact_orders> on 2025-05-08 14:58:40.551626+00:00
[2025-05-08T14:59:42.048+0000] {standard_task_runner.py:63} INFO - Started process 10867 to run task
[2025-05-08T14:59:42.052+0000] {standard_task_runner.py:90} INFO - Running: ['***', 'tasks', 'run', 'e_commerce_dw_etl_decorator', 'load.load_fact_orders', 'manual__2025-05-08T14:58:40.551626+00:00', '--job-id', '121', '--raw', '--subdir', 'DAGS_FOLDER/ecommerce_dw_dag.py', '--cfg-path', '/tmp/tmpj3tggkuc']
[2025-05-08T14:59:42.056+0000] {standard_task_runner.py:91} INFO - Job 121: Subtask load.load_fact_orders
[2025-05-08T14:59:42.205+0000] {task_command.py:426} INFO - Running <TaskInstance: e_commerce_dw_etl_decorator.load.load_fact_orders manual__2025-05-08T14:58:40.551626+00:00 [running]> on host ebff8b55cad8
[2025-05-08T14:59:42.439+0000] {taskinstance.py:2648} INFO - Exporting env vars: AIRFLOW_CTX_DAG_OWNER='***' AIRFLOW_CTX_DAG_ID='e_commerce_dw_etl_decorator' AIRFLOW_CTX_TASK_ID='load.load_fact_orders' AIRFLOW_CTX_EXECUTION_DATE='2025-05-08T14:58:40.551626+00:00' AIRFLOW_CTX_TRY_NUMBER='1' AIRFLOW_CTX_DAG_RUN_ID='manual__2025-05-08T14:58:40.551626+00:00'
[2025-05-08T14:59:42.441+0000] {taskinstance.py:430} INFO - ::endgroup::
[2025-05-08T14:59:42.447+0000] {taskinstance.py:441} INFO - ::group::Post task execution logs
[2025-05-08T14:59:42.450+0000] {taskinstance.py:2905} ERROR - Task failed with exception
Traceback (most recent call last):
  File "/home/airflow/.local/lib/python3.10/site-packages/airflow/models/taskinstance.py", line 465, in _execute_task
    result = _execute_callable(context=context, **execute_callable_kwargs)
  File "/home/airflow/.local/lib/python3.10/site-packages/airflow/models/taskinstance.py", line 432, in _execute_callable
    return execute_callable(context=context, **execute_callable_kwargs)
  File "/home/airflow/.local/lib/python3.10/site-packages/airflow/models/baseoperator.py", line 401, in wrapper
    return func(self, *args, **kwargs)
  File "/home/airflow/.local/lib/python3.10/site-packages/airflow/operators/python.py", line 235, in execute
    return_value = self.execute_callable()
  File "/home/airflow/.local/lib/python3.10/site-packages/airflow/operators/python.py", line 252, in execute_callable
    return self.python_callable(*self.op_args, **self.op_kwargs)
  File "/opt/airflow/dags/load_to_warehouse.py", line 14, in load_to_warehouse
    raise FileNotFoundError(f"Did not find latest {table_name}.")
FileNotFoundError: Did not find latest dim_fact_orders.
[2025-05-08T14:59:42.482+0000] {taskinstance.py:1206} INFO - Marking task as FAILED. dag_id=e_commerce_dw_etl_decorator, task_id=load.load_fact_orders, run_id=manual__2025-05-08T14:58:40.551626+00:00, execution_date=20250508T145840, start_date=20250508T145941, end_date=20250508T145942
[2025-05-08T14:59:42.506+0000] {standard_task_runner.py:110} ERROR - Failed to execute job 121 for task load.load_fact_orders (Did not find latest dim_fact_orders.; 10867)
[2025-05-08T14:59:42.554+0000] {local_task_job_runner.py:240} INFO - Task exited with return code 1
[2025-05-08T14:59:42.585+0000] {taskinstance.py:3503} INFO - 0 downstream tasks scheduled from follow-on schedule check
[2025-05-08T14:59:42.590+0000] {local_task_job_runner.py:222} INFO - ::endgroup::
