[2025-05-05T06:21:09.172+0000] {local_task_job_runner.py:120} INFO - ::group::Pre task execution logs
[2025-05-05T06:21:09.221+0000] {taskinstance.py:2076} INFO - Dependencies all met for dep_context=non-requeueable deps ti=<TaskInstance: first_dag.get_age manual__2025-05-05T06:21:08.040059+00:00 [queued]>
[2025-05-05T06:21:09.233+0000] {taskinstance.py:2076} INFO - Dependencies all met for dep_context=requeueable deps ti=<TaskInstance: first_dag.get_age manual__2025-05-05T06:21:08.040059+00:00 [queued]>
[2025-05-05T06:21:09.234+0000] {taskinstance.py:2306} INFO - Starting attempt 1 of 6
[2025-05-05T06:21:09.258+0000] {taskinstance.py:2330} INFO - Executing <Task(PythonOperator): get_age> on 2025-05-05 06:21:08.040059+00:00
[2025-05-05T06:21:09.271+0000] {standard_task_runner.py:63} INFO - Started process 3245 to run task
[2025-05-05T06:21:09.275+0000] {standard_task_runner.py:90} INFO - Running: ['***', 'tasks', 'run', 'first_dag', 'get_age', 'manual__2025-05-05T06:21:08.040059+00:00', '--job-id', '39', '--raw', '--subdir', 'DAGS_FOLDER/test.py', '--cfg-path', '/tmp/tmps7bdtyxm']
[2025-05-05T06:21:09.279+0000] {standard_task_runner.py:91} INFO - Job 39: Subtask get_age
[2025-05-05T06:21:09.389+0000] {task_command.py:426} INFO - Running <TaskInstance: first_dag.get_age manual__2025-05-05T06:21:08.040059+00:00 [running]> on host 27601e035d0f
[2025-05-05T06:21:09.613+0000] {taskinstance.py:2648} INFO - Exporting env vars: AIRFLOW_CTX_DAG_OWNER='khanhle' AIRFLOW_CTX_DAG_ID='first_dag' AIRFLOW_CTX_TASK_ID='get_age' AIRFLOW_CTX_EXECUTION_DATE='2025-05-05T06:21:08.040059+00:00' AIRFLOW_CTX_TRY_NUMBER='1' AIRFLOW_CTX_DAG_RUN_ID='manual__2025-05-05T06:21:08.040059+00:00'
[2025-05-05T06:21:09.620+0000] {taskinstance.py:430} INFO - ::endgroup::
[2025-05-05T06:21:09.649+0000] {taskinstance.py:441} INFO - ::group::Post task execution logs
[2025-05-05T06:21:09.651+0000] {taskinstance.py:2905} ERROR - Task failed with exception
Traceback (most recent call last):
  File "/home/airflow/.local/lib/python3.10/site-packages/airflow/models/taskinstance.py", line 465, in _execute_task
    result = _execute_callable(context=context, **execute_callable_kwargs)
  File "/home/airflow/.local/lib/python3.10/site-packages/airflow/models/taskinstance.py", line 432, in _execute_callable
    return execute_callable(context=context, **execute_callable_kwargs)
  File "/home/airflow/.local/lib/python3.10/site-packages/airflow/models/baseoperator.py", line 401, in wrapper
    return func(self, *args, **kwargs)
  File "/home/airflow/.local/lib/python3.10/site-packages/airflow/operators/python.py", line 235, in execute
    return_value = self.execute_callable()
  File "/home/airflow/.local/lib/python3.10/site-packages/airflow/operators/python.py", line 252, in execute_callable
    return self.python_callable(*self.op_args, **self.op_kwargs)
  File "/opt/airflow/dags/test.py", line 22, in get_age
    ti.xcom_push(keys='age', value=19)
  File "/home/airflow/.local/lib/python3.10/site-packages/airflow/utils/session.py", line 79, in wrapper
    return func(*args, session=session, **kwargs)
TypeError: TaskInstance.xcom_push() got an unexpected keyword argument 'keys'
[2025-05-05T06:21:09.676+0000] {taskinstance.py:1206} INFO - Marking task as UP_FOR_RETRY. dag_id=first_dag, task_id=get_age, run_id=manual__2025-05-05T06:21:08.040059+00:00, execution_date=20250505T062108, start_date=20250505T062109, end_date=20250505T062109
[2025-05-05T06:21:09.704+0000] {standard_task_runner.py:110} ERROR - Failed to execute job 39 for task get_age (TaskInstance.xcom_push() got an unexpected keyword argument 'keys'; 3245)
[2025-05-05T06:21:09.734+0000] {local_task_job_runner.py:240} INFO - Task exited with return code 1
[2025-05-05T06:21:09.766+0000] {taskinstance.py:3503} INFO - 0 downstream tasks scheduled from follow-on schedule check
[2025-05-05T06:21:09.770+0000] {local_task_job_runner.py:222} INFO - ::endgroup::
